Workbook

Sheet Sheet1
A1: Page 1 | B1: النظام : | C1: المخازن | F1: التاريخ : | G1: 31-10-2026
B2: الشركة : | C2: شركة اكاف العربية | E2: رصيد المخزن فى يوم معين /كمية | F2: الوقت : | I2: 01:02 PM
G3: 206 | H3: : | I3: 1
F4: صفحة :
B5: السنة : | C5: 2026
B6: من كود فرع | D6: 1 | E6: شركة إكاف العربية
B7: إلى كود فرع | D7: 1 | E7: شركة إكاف العربية
B8: من كود مخزن
B9: الى كود مخزن
B10: من كود صنف
B11: الى كود صنف
B12: ارصدة صفرية | D12: لا
B13: حتى تاريخ | D13: 31-10-2026
A14: Page 2 | B14: النظام : | C14: المخازن | G14: التاريخ : | H14: 31-10-2026
B15: الشركة : | C15: شركة اكاف العربية | E15: رصيد المخزن فى يوم معين /كمية | G15: الوقت : | H15: 01:02 PM
B16: السنة : | C16: 2026 | G16: صفحة : | H16: 206 | I16: : | J16: 2
E17: حتى تاريخ | F17: 31-10-2026
B18: كود الفرع | D18: 1 | E18: شركة إكاف العربية
B19: كود المخزن | D19: 1 | E19: الانتاج التام(الرياض
B20: كود الصنف | D20: اسم الصنف | F20: الوحدة | G20: رصيد الصنف
B21: 07014001520031 | D21: علب كسوة الكعبة كبيرة تام | F21: قطعة | G21: 4
B22: 07014001520041 | D22: علب كسوة الكعبة وسط تام | F22: قطعة | G22: 33
B23: 07014001520042 | D23: علب كسوة الكعبة قنديل يارحمنK-005 | F23: قطعة | G23: 4
B24: 07014001520043 | D24: علب كسوة الكعبة قنديل الله اكبر K-002 | F24: قطعة | G24: 4
B25: 07014001520044 | D25: علب كسوة الكعبة قنديل الحمد الله K-003 | F25: قطعة | G25: 7
B26: 07014001520045 | D26: علب كسوة الكعبة قنديل ياحي ياقيوم K-007 | F26: قطعة | G26: 6
B27: 07014001520046 | D27: علب كسو الكعبة قند ان اول بيت وضع للناس | F27: قطعة | G27: 7
B28: 07014001520051 | D28: علب كسوة الكعبة صغيرة تام | F28: قطعة | G28: 8
B29: 07 | D29: اكسسورا | G29: 73
B30: 07000222100004008015 | D30: ازياء مناسبات خ1 اكاف يوني سديري ع رجالL | F30: قطعة | G30: 37
B31: 07000222100004 | D31: ازياء مناسبات خ1 اكاف يوني سديري ع رجالL | G31: 37
B32: 10420312104968 | D32: كتان راقي بلوكم ط مطرززر شباب I4968 | F32: درزن | G32: 4
B33: 13220111024280 | D33: فاس اكاف بلو مغربي نص كم مطرز زر رجالي | F33: درزن | G33: 7.75
B34: 14220911984 | D34: شانيه تريند مغربي نص كم مطرز رجال مشكل م | F34: درزن | G34: 0.25
B35: 14230911984 | D35: تريند مغربي قلعةنص كم مطرز رجال مشكل م | F35: درزن | G35: 0.25
B36: 17970121024192 | D36: سيهان اكاف اورانج نص كم مطرز سحاب رجال B | F36: درزن | G36: 15
B37: 17970211024159 | D37: سيهان اكاف اورانج نص كم عادي أزرار رجالB | F37: درزن | G37: 28
B38: 1 | D38: منتج تام | G38: 55.25
B39: 100311 | D39: مشكل بدون استيكر رجالى عادى | F39: قطعة | G39: 33
B40: 100312 | D40: مشكل بدون استيكر رجالى مطرز | F40: قطعة | G40: 141
...

Sheet مخزون مفكوك
A1: كود الصنف | B1: اسم الصنف | C1: الوحدة | D1: الخامة | E1: الماركة | F1: الموديل | G1: الريشيو | H1: اللون | I1: رقم الموديل | J1: 1 - الانتاج التام(الرياض | K1: 2 - م جدة الرئيسى | L1: 4 - شمال الغربى جده ياسر | M1: 9 - التصديرمحمد ع الفتاح | N1: 11 - جنوب مكة اسماعيل | O1: 12 - مكة عصام ابوالمكارم | P1: 13 - الجملة الرياض | Q1: 17 - شرق الرياض قصي | R1: 18 - الدمام محمود سامي | S1: 28 - خميس مشيط مراد | T1: 31 - هداياومبيعات الإدارة | U1: 32 - مستودع مكة المكرمة | V1: 33 - المدينة ضياء السيقل | W1: 36 - محمد سعد مكة | X1: 39 - رامي المدينة | Y1: 48 - مخزن غرب محمد جودة | Z1: 50 - الموقع الالكترونى | AA1: 55 - القصيم منير الاحمدي | AB1: 90 - الخام ( الرياض ) | AC1: 92 - مخزن الملحقات الوقيع | AD1: 93 - القص | AE1: 94 - ملحقات الخياطة | AF1: 95 - استهلاكات الملحقات | AG1: الإجمالي
A2: 07014001520031 | B2: علب كسوة الكعبة كبيرة تام | C2: قطعة | J2: 4 | K2: 554 | AG2: =SUM(J2:AF2) -> 558
A3: 07014001520041 | B3: علب كسوة الكعبة وسط تام | C3: قطعة | J3: 33 | K3: 461 | AG3: =SUM(J3:AF3) -> 494
A4: 07014001520042 | B4: علب كسوة الكعبة قنديل يارحمنK-005 | C4: قطعة | J4: 4 | AG4: =SUM(J4:AF4) -> 4
A5: 07014001520043 | B5: علب كسوة الكعبة قنديل الله اكبر K-002 | C5: قطعة | J5: 4 | AG5: =SUM(J5:AF5) -> 4
A6: 07014001520044 | B6: علب كسوة الكعبة قنديل الحمد الله K-003 | C6: قطعة | J6: 7 | AG6: =SUM(J6:AF6) -> 7
A7: 07014001520045 | B7: علب كسوة الكعبة قنديل ياحي ياقيوم K-007 | C7: قطعة | J7: 6 | AG7: =SUM(J7:AF7) -> 6
A8: 07014001520046 | B8: علب كسو الكعبة قند ان اول بيت وضع للناس | C8: قطعة | J8: 7 | AG8: =SUM(J8:AF8) -> 7
A9: 07014001520051 | B9: علب كسوة الكعبة صغيرة تام | C9: قطعة | J9: 8 | K9: 12 | AG9: =SUM(J9:AF9) -> 20
A10: 07000222100004008015 | B10: ازياء مناسبات خ1 اكاف يوني سديري ع رجالL | C10: قطعة | J10: 37 | K10: 1 | AG10: =SUM(J10:AF10) -> 38
A11: 10420312104968 | B11: كتان راقي بلوكم ط مطرززر شباب I4968 | C11: درزن | D11: كتان راقي | E11: اكاف بلو | F11: كم طويل مطرز | G11: I | H11: ملون | I11: 968 | J11: 4 | K11: 42 | R11: 6 | AA11: 6 | AG11: =SUM(J11:AF11) -> 58
A12: 13220111024280 | B12: فاس اكاف بلو مغربي نص كم مطرز زر رجالي | C12: درزن | D12: فاس | E12: اكاف بلو | F12: نص كم مطرز | G12: B | H12: ملون | I12: 280 | J12: 7.75 | R12: 5 | X12: 6 | AG12: =SUM(J12:AF12) -> 18.75
A13: 14220911984 | B13: شانيه تريند مغربي نص كم مطرز رجال مشكل م | C13: درزن | D13: شانيه ( ترند ادلاست ) | E13: اكاف بلو | F13: مغربي مطرز نص كم | G13: مقاسات مشكلة | H13: ملون | J13: 0.25 | T13: 0.083 | AG13: =SUM(J13:AF13) -> 0.333
A14: 14230911984 | B14: تريند مغربي قلعةنص كم مطرز رجال مشكل م | C14: درزن | D14: شانيه ( ترند ادلاست ) | E14: القلعة | F14: مغربي مطرز نص كم | G14: مقاسات مشكلة | H14: ملون | J14: 0.25 | AG14: =SUM(J14:AF14) -> 0.25
A15: 17970121024192 | B15: سيهان اكاف اورانج نص كم مطرز سحاب رجال B | C15: درزن | D15: سيهان | E15: اكاف اورانج | F15: نص كم مطرز | G15: B | H15: ملون | I15: 192 | J15: 15 | K15: 6 | R15: 10 | S15: 4 | U15: 23 | V15: 1 | Z15: 5.333 | AA15: 11 | AG15: =SUM(J15:AF15) -> 75.333
A16: 17970211024159 | B16: سيهان اكاف اورانج نص كم عادي أزرار رجالB | C16: درزن | D16: سيهان | E16: اكاف اورانج | F16: نص كم عادي | G16: B | H16: ملون | I16: 159 | J16: 28 | K16: 11 | R16: 11 | S16: 4 | V16: 10 | X16: 4 | Z16: 5.083 | AG16: =SUM(J16:AF16) -> 73.083
A17: 100311 | B17: مشكل بدون استيكر رجالى عادى | C17: قطعة | J17: 33 | K17: 68 | AG17: =SUM(J17:AF17) -> 101
A18: 100312 | B18: مشكل بدون استيكر رجالى مطرز | C18: قطعة | J18: 141 | K18: 118 | AG18: =SUM(J18:AF18) -> 259
A19: 100321 | B19: مشكل بدون استيكر شبابى عادى | C19: قطعة | J19: 13 | AG19: =SUM(J19:AF19) -> 13
A20: 100322 | B20: مشكل بدون استيكر شبابى مطرز | C20: قطعة | J20: 12 | K20: 2 | AG20: =SUM(J20:AF20) -> 14
A21: 100331 | B21: مشكل بدون استيكر ولادى عادى | C21: قطعة | J21: 6 | AG21: =SUM(J21:AF21) -> 6
A22: 100332 | B22: مشكل بدون استيكر ولادى مطرز | C22: قطعة | J22: 29 | K22: 70 | AG22: =SUM(J22:AF22) -> 99
A23: 10110111060281 | B23: كوشوبو اكاف نص مطرز زر رجال F تطريزة 281 | C23: درزن | D23: كوشوبو | E23: إكاف | F23: نص كم مطرز | G23: F | I23: 281 | J23: 0.25 | AG23: =SUM(J23:AF23) -> 0.25
A24: 10110112101018 | B24: كوشوبو إكاف نص كم مطرز زر شبابىI1018 | C24: درزن | D24: كوشوبو | E24: إكاف | F24: نص كم مطرز | G24: I | H24: ابيض | I24: 018 | J24: 0.25 | AG24: =SUM(J24:AF24) -> 0.25
A25: 10110113124 | B25: كوشوبو إكاف نص مطرز زر ولادىK ملون | C25: درزن | D25: كوشوبو | E25: إكاف | F25: نص كم مطرز | G25: K | H25: ملون | J25: 0.583 | AG25: =SUM(J25:AF25) -> 0.583
A26: 10110213128048 | B26: كوشوبو إكاف نص عادي زر ولاديK8048 | C26: درزن | D26: كوشوبو | E26: إكاف | F26: نص كم عادي | G26: K | I26: 048 | J26: 1 | AG26: =SUM(J26:AF26) -> 1
A27: 1012551198464 | B27: كوشوبو اكاف بلونص كم مطر زر رجال مش64 | C27: قطعة | D27: كوشوبو | E27: اكاف بلو | F27: نصف كم مطرز عرض 32 | G27: 64 | H27: ملون | J27: 6 | AG27: =SUM(J27:AF27) -> 6
A28: 10120111023344 | B28: كوشوبو اكاف بلو نص كم مطرز زررجالي B3344 | C28: درزن | D28: كوشوبو | E28: اكاف بلو | F28: نص كم مطرز | G28: B | H28: اسود | I28: 344 | J28: 1 | V28: 5 | AA28: 6 | AG28: =SUM(J28:AF28) -> 12
A29: 1012011198354 | B29: كوشوبو بلو نص كم مطرز زر رجالي مشكل 54 | C29: قطعة | D29: كوشوبو | E29: اكاف بلو | F29: نص كم مطرز | G29: 54 | H29: اسود | J29: 14 | AG29: =SUM(J29:AF29) -> 14
A30: 10120111984 | B30: كوشوبو بلو نص كم مطرز زر رجالي مشكل | C30: درزن | D30: كوشوبو | E30: اكاف بلو | F30: نص كم مطرز | G30: مقاسات مشكلة | H30: ملون | J30: 0.25 | AG30: =SUM(J30:AF30) -> 0.25
A31: 10120111023413 | B31: كوشوبو اكاف بلو نص كم مطرز زررجالي B3413 | C31: درزن | D31: كوشوبو | E31: اكاف بلو | F31: نص كم مطرز | G31: B | H31: اسود | I31: 413 | J31: 43 | R31: 3 | S31: 6 | AG31: =SUM(J31:AF31) -> 52
A32: 10120111057428 | B32: كوشوبو بلو نص كم مطرز زر رجاليE-7428 | C32: درزن | D32: كوشوبو | E32: اكاف بلو | F32: نص كم مطرز | G32: E | I32: 428 | J32: 0.25 | AG32: =SUM(J32:AF32) -> 0.25
A33: 10120112984 | B33: كوشوبو بلو نص كم مطرز زر شباب مشكل ملون | C33: درزن | D33: كوشوبو | E33: اكاف بلو | F33: نص كم مطرز | G33: مقاسات مشكلة | H33: ملون | J33: 0.833 | K33: 0.583 | AG33: =SUM(J33:AF33) -> 1.416
A34: 10120113124021 | B34: كوشوبواكاف بلو نص كم مطرز زرولاديK4021 | C34: درزن | D34: كوشوبو | E34: اكاف بلو | F34: نص كم مطرز | G34: K | H34: ملون | I34: 021 | J34: 0.333 | AG34: =SUM(J34:AF34) -> 0.333
A35: 10120113124728 | B35: كوشوبواكاف بلو نص كم مطرز زرولاديK4728 | C35: درزن | D35: كوشوبو | E35: اكاف بلو | F35: نص كم مطرز | G35: K | H35: ملون | I35: 728 | J35: 10 | K35: 1 | S35: 4 | U35: 34 | AG35: =SUM(J35:AF35) -> 49
A36: 10120113124964 | B36: كوشوبواكاف بلو نص كم مطرز زرولاديK4964 | C36: درزن | D36: كوشوبو | E36: اكاف بلو | F36: نص كم مطرز | G36: K | H36: ملون | I36: 964 | J36: 10 | K36: 69 | R36: 1 | AG36: =SUM(J36:AF36) -> 80
A37: 10120113984 | B37: كوشوبواكاف بلو نص كم مطرز زرولادي مشكل م | C37: درزن | D37: كوشوبو | E37: اكاف بلو | F37: نص كم مطرز | G37: مقاسات مشكلة | H37: ملون | J37: 1.042 | K37: 0.208 | AG37: =SUM(J37:AF37) -> 1.25
A38: 10120211023157 | B38: كوشوبو بلو نص كم عادى زررجال B3157 | C38: درزن | D38: كوشوبو | E38: اكاف بلو | F38: نص كم عادي | G38: B | H38: اسود | I38: 157 | J38: 4 | K38: 6 | R38: 2.667 | S38: 12 | V38: 4 | X38: 5 | Z38: 5.5 | AG38: =SUM(J38:AF38) -> 39.167
A39: 10120211984 | B39: كوشوبو بلو نص كم عادى زررجال مشكل ملون | C39: درزن | D39: كوشوبو | E39: اكاف بلو | F39: نص كم عادي | G39: مقاسات مشكلة | H39: ملون | J39: 1.083 | AG39: =SUM(J39:AF39) -> 1.083
A40: 10120212984 | B40: كوشوبو بلو نص كم عادى زر شباب مشكل ملون | C40: درزن | D40: كوشوبو | E40: اكاف بلو | F40: نص كم عادي | G40: مقاسات مشكلة | H40: ملون | J40: 0.167 | AG40: =SUM(J40:AF40) -> 0.167
...

Sheet المستودعات الرئيسية
A1: كود الصنف | B1: اسم الصنف | C1: الوحدة | D1: الخامة | E1: الماركة | F1: الموديل | G1: الريشيو | H1: اللون | I1: رقم الموديل | J1: 1 - الانتاج التام(الرياض | K1: 2 - م جدة الرئيسى | L1: 32 - مستودع مكة المكرمة | M1: المستودعات الرئيسية
A2: ='مخزون مفكوك'!A2&"" -> 07014001520031 | B2: ='مخزون مفكوك'!B2&"" -> علب كسوة الكعبة كبيرة تام | C2: ='مخزون مفكوك'!C2&"" -> قطعة | D2: ='مخزون مفكوك'!D2&"" | E2: ='مخزون مفكوك'!E2&"" | F2: ='مخزون مفكوك'!F2&"" | G2: ='مخزون مفكوك'!G2&"" | H2: ='مخزون مفكوك'!H2&"" | I2: ='مخزون مفكوك'!I2&"" | J2: =N('مخزون مفكوك'!J2) -> 4 | K2: =N('مخزون مفكوك'!K2) -> 554 | L2: =N('مخزون مفكوك'!U2) -> 0 | M2: =SUM(J2:L2) -> 558
A3: ='مخزون مفكوك'!A3&"" -> 07014001520041 | B3: ='مخزون مفكوك'!B3&"" -> علب كسوة الكعبة وسط تام | C3: ='مخزون مفكوك'!C3&"" -> قطعة | D3: ='مخزون مفكوك'!D3&"" | E3: ='مخزون مفكوك'!E3&"" | F3: ='مخزون مفكوك'!F3&"" | G3: ='مخزون مفكوك'!G3&"" | H3: ='مخزون مفكوك'!H3&"" | I3: ='مخزون مفكوك'!I3&"" | J3: =N('مخزون مفكوك'!J3) -> 33 | K3: =N('مخزون مفكوك'!K3) -> 461 | L3: =N('مخزون مفكوك'!U3) -> 0 | M3: =SUM(J3:L3) -> 494
A4: ='مخزون مفكوك'!A4&"" -> 07014001520042 | B4: ='مخزون مفكوك'!B4&"" -> علب كسوة الكعبة قنديل يارحمنK-005 | C4: ='مخزون مفكوك'!C4&"" -> قطعة | D4: ='مخزون مفكوك'!D4&"" | E4: ='مخزون مفكوك'!E4&"" | F4: ='مخزون مفكوك'!F4&"" | G4: ='مخزون مفكوك'!G4&"" | H4: ='مخزون مفكوك'!H4&"" | I4: ='مخزون مفكوك'!I4&"" | J4: =N('مخزون مفكوك'!J4) -> 4 | K4: =N('مخزون مفكوك'!K4) -> 0 | L4: =N('مخزون مفكوك'!U4) -> 0 | M4: =SUM(J4:L4) -> 4
A5: ='مخزون مفكوك'!A5&"" -> 07014001520043 | B5: ='مخزون مفكوك'!B5&"" -> علب كسوة الكعبة قنديل الله اكبر K-002 | C5: ='مخزون مفكوك'!C5&"" -> قطعة | D5: ='مخزون مفكوك'!D5&"" | E5: ='مخزون مفكوك'!E5&"" | F5: ='مخزون مفكوك'!F5&"" | G5: ='مخزون مفكوك'!G5&"" | H5: ='مخزون مفكوك'!H5&"" | I5: ='مخزون مفكوك'!I5&"" | J5: =N('مخزون مفكوك'!J5) -> 4 | K5: =N('مخزون مفكوك'!K5) -> 0 | L5: =N('مخزون مفكوك'!U5) -> 0 | M5: =SUM(J5:L5) -> 4
A6: ='مخزون مفكوك'!A6&"" -> 07014001520044 | B6: ='مخزون مفكوك'!B6&"" -> علب كسوة الكعبة قنديل الحمد الله K-003 | C6: ='مخزون مفكوك'!C6&"" -> قطعة | D6: ='مخزون مفكوك'!D6&"" | E6: ='مخزون مفكوك'!E6&"" | F6: ='مخزون مفكوك'!F6&"" | G6: ='مخزون مفكوك'!G6&"" | H6: ='مخزون مفكوك'!H6&"" | I6: ='مخزون مفكوك'!I6&"" | J6: =N('مخزون مفكوك'!J6) -> 7 | K6: =N('مخزون مفكوك'!K6) -> 0 | L6: =N('مخزون مفكوك'!U6) -> 0 | M6: =SUM(J6:L6) -> 7
A7: ='مخزون مفكوك'!A7&"" -> 07014001520045 | B7: ='مخزون مفكوك'!B7&"" -> علب كسوة الكعبة قنديل ياحي ياقيوم K-007 | C7: ='مخزون مفكوك'!C7&"" -> قطعة | D7: ='مخزون مفكوك'!D7&"" | E7: ='مخزون مفكوك'!E7&"" | F7: ='مخزون مفكوك'!F7&"" | G7: ='مخزون مفكوك'!G7&"" | H7: ='مخزون مفكوك'!H7&"" | I7: ='مخزون مفكوك'!I7&"" | J7: =N('مخزون مفكوك'!J7) -> 6 | K7: =N('مخزون مفكوك'!K7) -> 0 | L7: =N('مخزون مفكوك'!U7) -> 0 | M7: =SUM(J7:L7) -> 6
A8: ='مخزون مفكوك'!A8&"" -> 07014001520046 | B8: ='مخزون مفكوك'!B8&"" -> علب كسو الكعبة قند ان اول بيت وضع للناس | C8: ='مخزون مفكوك'!C8&"" -> قطعة | D8: ='مخزون مفكوك'!D8&"" | E8: ='مخزون مفكوك'!E8&"" | F8: ='مخزون مفكوك'!F8&"" | G8: ='مخزون مفكوك'!G8&"" | H8: ='مخزون مفكوك'!H8&"" | I8: ='مخزون مفكوك'!I8&"" | J8: =N('مخزون مفكوك'!J8) -> 7 | K8: =N('مخزون مفكوك'!K8) -> 0 | L8: =N('مخزون مفكوك'!U8) -> 0 | M8: =SUM(J8:L8) -> 7
A9: ='مخزون مفكوك'!A9&"" -> 07014001520051 | B9: ='مخزون مفكوك'!B9&"" -> علب كسوة الكعبة صغيرة تام | C9: ='مخزون مفكوك'!C9&"" -> قطعة | D9: ='مخزون مفكوك'!D9&"" | E9: ='مخزون مفكوك'!E9&"" | F9: ='مخزون مفكوك'!F9&"" | G9: ='مخزون مفكوك'!G9&"" | H9: ='مخزون مفكوك'!H9&"" | I9: ='مخزون مفكوك'!I9&"" | J9: =N('مخزون مفكوك'!J9) -> 8 | K9: =N('مخزون مفكوك'!K9) -> 12 | L9: =N('مخزون مفكوك'!U9) -> 0 | M9: =SUM(J9:L9) -> 20
A10: ='مخزون مفكوك'!A10&"" -> 07000222100004008015 | B10: ='مخزون مفكوك'!B10&"" -> ازياء مناسبات خ1 اكاف يوني سديري ع رجالL | C10: ='مخزون مفكوك'!C10&"" -> قطعة | D10: ='مخزون مفكوك'!D10&"" | E10: ='مخزون مفكوك'!E10&"" | F10: ='مخزون مفكوك'!F10&"" | G10: ='مخزون مفكوك'!G10&"" | H10: ='مخزون مفكوك'!H10&"" | I10: ='مخزون مفكوك'!I10&"" | J10: =N('مخزون مفكوك'!J10) -> 37 | K10: =N('مخزون مفكوك'!K10) -> 1 | L10: =N('مخزون مفكوك'!U10) -> 0 | M10: =SUM(J10:L10) -> 38
A11: ='مخزون مفكوك'!A11&"" -> 10420312104968 | B11: ='مخزون مفكوك'!B11&"" -> كتان راقي بلوكم ط مطرززر شباب I4968 | C11: ='مخزون مفكوك'!C11&"" -> درزن | D11: ='مخزون مفكوك'!D11&"" -> كتان راقي | E11: ='مخزون مفكوك'!E11&"" -> اكاف بلو | F11: ='مخزون مفكوك'!F11&"" -> كم طويل مطرز | G11: ='مخزون مفكوك'!G11&"" -> I | H11: ='مخزون مفكوك'!H11&"" -> ملون | I11: ='مخزون مفكوك'!I11&"" -> 968 | J11: =N('مخزون مفكوك'!J11) -> 4 | K11: =N('مخزون مفكوك'!K11) -> 42 | L11: =N('مخزون مفكوك'!U11) -> 0 | M11: =SUM(J11:L11) -> 46
A12: ='مخزون مفكوك'!A12&"" -> 13220111024280 | B12: ='مخزون مفكوك'!B12&"" -> فاس اكاف بلو مغربي نص كم مطرز زر رجالي | C12: ='مخزون مفكوك'!C12&"" -> درزن | D12: ='مخزون مفكوك'!D12&"" -> فاس | E12: ='مخزون مفكوك'!E12&"" -> اكاف بلو | F12: ='مخزون مفكوك'!F12&"" -> نص كم مطرز | G12: ='مخزون مفكوك'!G12&"" -> B | H12: ='مخزون مفكوك'!H12&"" -> ملون | I12: ='مخزون مفكوك'!I12&"" -> 280 | J12: =N('مخزون مفكوك'!J12) -> 7.75 | K12: =N('مخزون مفكوك'!K12) -> 0 | L12: =N('مخزون مفكوك'!U12) -> 0 | M12: =SUM(J12:L12) -> 7.75
A13: ='مخزون مفكوك'!A13&"" -> 14220911984 | B13: ='مخزون مفكوك'!B13&"" -> شانيه تريند مغربي نص كم مطرز رجال مشكل م | C13: ='مخزون مفكوك'!C13&"" -> درزن | D13: ='مخزون مفكوك'!D13&"" -> شانيه ( ترند ادلاست ) | E13: ='مخزون مفكوك'!E13&"" -> اكاف بلو | F13: ='مخزون مفكوك'!F13&"" -> مغربي مطرز نص كم | G13: ='مخزون مفكوك'!G13&"" -> مقاسات مشكلة | H13: ='مخزون مفكوك'!H13&"" -> ملون | I13: ='مخزون مفكوك'!I13&"" | J13: =N('مخزون مفكوك'!J13) -> 0.25 | K13: =N('مخزون مفكوك'!K13) -> 0 | L13: =N('مخزون مفكوك'!U13) -> 0 | M13: =SUM(J13:L13) -> 0.25
... A1502: ='مخزون مفكوك'!A1502&"" -> 10420111014352 | B1502: ='مخزون مفكوك'!B1502&"" -> كتان راقي بلو نص كم مطرز زر رجالي A4352 | C1502: ='مخزون مفكوك'!C1502&"" -> درزن | D1502: ='مخزون مفكوك'!D1502&"" -> كتان راقي | E1502: ='مخزون مفكوك'!E1502&"" -> اكاف بلو | F1502: ='مخزون مفكوك'!F1502&"" -> نص كم مطرز | G1502: ='مخزون مفكوك'!G1502&"" -> A | H1502: ='مخزون مفكوك'!H1502&"" -> ملون | I1502: ='مخزون مفكوك'!I1502&"" -> 352 | J1502: =N('مخزون مفكوك'!J1502) -> 0 | K1502: =N('مخزون مفكوك'!K1502) -> 0 | L1502: =N('مخزون مفكوك'!U1502) -> 8 | M1502: =SUM(J1502:L1502) -> 8
A1503: ='مخزون مفكوك'!A1512&"" -> 10420112994773 | B1503: ='مخزون مفكوك'!B1512&"" -> كتان راقي بلو نص كم مطرز زر شبابى SP4773 | C1503: ='مخزون مفكوك'!C1512&"" -> درزن | D1503: ='مخزون مفكوك'!D1512&"" -> كتان راقي | E1503: ='مخزون مفكوك'!E1512&"" -> اكاف بلو | F1503: ='مخزون مفكوك'!F1512&"" -> نص كم مطرز | G1503: ='مخزون مفكوك'!G1512&"" -> SPECIAL | H1503: ='مخزون مفكوك'!H1512&"" -> ملون | I1503: ='مخزون مفكوك'!I1512&"" -> 773 | J1503: =N('مخزون مفكوك'!J1512) -> 0 | K1503: =N('مخزون مفكوك'!K1512) -> 0 | L1503: =N('مخزون مفكوك'!U1512) -> 10 | M1503: =SUM(J1503:L1503) -> 10
A1504: ='مخزون مفكوك'!A1520&"" -> 10421621024168 | B1504: ='مخزون مفكوك'!B1520&"" -> كتان راقي بلو كم ط مطرز مخصر سح رجاB4168 | C1504: ='مخزون مفكوك'!C1520&"" -> درزن | D1504: ='مخزون مفكوك'!D1520&"" -> كتان راقي | E1504: ='مخزون مفكوك'!E1520&"" -> اكاف بلو | F1504: ='مخزون مفكوك'!F1520&"" -> كم طويل مطرز مع قبع ( مخصر ) | G1504: ='مخزون مفكوك'!G1520&"" -> B | H1504: ='مخزون مفكوك'!H1520&"" -> ملون | I1504: ='مخزون مفكوك'!I1520&"" -> 168 | J1504: =N('مخزون مفكوك'!J1520) -> 0 | K1504: =N('مخزون مفكوك'!K1520) -> 0 | L1504: =N('مخزون مفكوك'!U1520) -> 18.917 | M1504: =SUM(J1504:L1504) -> 18.917
A1505: ='مخزون مفكوك'!A1524&"" -> 10620111024919 | B1505: ='مخزون مفكوك'!B1524&"" -> بولستر لمعة بلو نص مطرز زر رجال ملون B | C1505: ='مخزون مفكوك'!C1524&"" -> درزن | D1505: ='مخزون مفكوك'!D1524&"" -> بولستر لمعة | E1505: ='مخزون مفكوك'!E1524&"" -> اكاف بلو | F1505: ='مخزون مفكوك'!F1524&"" -> نص كم مطرز | G1505: ='مخزون مفكوك'!G1524&"" -> B | H1505: ='مخزون مفكوك'!H1524&"" -> ملون | I1505: ='مخزون مفكوك'!I1524&"" -> 919 | J1505: =N('مخزون مفكوك'!J1524) -> 0 | K1505: =N('مخزون مفكوك'!K1524) -> 0 | L1505: =N('مخزون مفكوك'!U1524) -> 4 | M1505: =SUM(J1505:L1505) -> 4
A1506: ='مخزون مفكوك'!A1539&"" -> 1052691198454 | B1506: ='مخزون مفكوك'!B1539&"" -> كتان سولداكاف بلو كم مطرز زر رجالي مشكل | C1506: ='مخزون مفكوك'!C1539&"" -> قطعة | D1506: ='مخزون مفكوك'!D1539&"" -> كتان سولد | E1506: ='مخزون مفكوك'!E1539&"" -> اكاف بلو | F1506: ='مخزون مفكوك'!F1539&"" -> كم مطرز عرض 22 | G1506: ='مخزون مفكوك'!G1539&"" -> 54 | H1506: ='مخزون مفكوك'!H1539&"" -> ملون | I1506: ='مخزون مفكوك'!I1539&"" | J1506: =N('مخزون مفكوك'!J1539) -> 0 | K1506: =N('مخزون مفكوك'!K1539) -> 0 | L1506: =N('مخزون مفكوك'!U1539) -> 12 | M1506: =SUM(J1506:L1506) -> 12
A1507: ='مخزون مفكوك'!A1540&"" -> 1052701198458 | B1507: ='مخزون مفكوك'!B1540&"" -> كتان سولداكاف بلو نص كم عادي زر رجالي مش | C1507: ='مخزون مفكوك'!C1540&"" -> قطعة | D1507: ='مخزون مفكوك'!D1540&"" -> كتان سولد | E1507: ='مخزون مفكوك'!E1540&"" -> اكاف بلو | F1507: ='مخزون مفكوك'!F1540&"" -> نصف كم عادى عرض 24 | G1507: ='مخزون مفكوك'!G1540&"" -> 58 | H1507: ='مخزون مفكوك'!H1540&"" -> ملون | I1507: ='مخزون مفكوك'!I1540&"" | J1507: =N('مخزون مفكوك'!J1540) -> 0 | K1507: =N('مخزون مفكوك'!K1540) -> 0 | L1507: =N('مخزون مفكوك'!U1540) -> 12 | M1507: =SUM(J1507:L1507) -> 12
A1508: ='مخزون مفكوك'!A1541&"" -> 1052701198460 | B1508: ='مخزون مفكوك'!B1541&"" -> كتان سولداكاف بلو نص كم عادي زر رجالي مش | C1508: ='مخزون مفكوك'!C1541&"" -> قطعة | D1508: ='مخزون مفكوك'!D1541&"" -> كتان سولد | E1508: ='مخزون مفكوك'!E1541&"" -> اكاف بلو | F1508: ='مخزون مفكوك'!F1541&"" -> نصف كم عادى عرض 24 | G1508: ='مخزون مفكوك'!G1541&"" -> 60 | H1508: ='مخزون مفكوك'!H1541&"" -> ملون | I1508: ='مخزون مفكوك'!I1541&"" | J1508: =N('مخزون مفكوك'!J1541) -> 0 | K1508: =N('مخزون مفكوك'!K1541) -> 0 | L1508: =N('مخزون مفكوك'!U1541) -> 5 | M1508: =SUM(J1508:L1508) -> 5
A1509: ='مخزون مفكوك'!A1542&"" -> 1022541198162 | B1509: ='مخزون مفكوك'!B1542&"" -> عماني رجالي كم ط عادي مشكل 62 | C1509: ='مخزون مفكوك'!C1542&"" -> قطعة | D1509: ='مخزون مفكوك'!D1542&"" -> بولستر عادي | E1509: ='مخزون مفكوك'!E1542&"" -> اكاف بلو | F1509: ='مخزون مفكوك'!F1542&"" -> كم عادى عرض 32 | G1509: ='مخزون مفكوك'!G1542&"" -> 62 | H1509: ='مخزون مفكوك'!H1542&"" -> ابيض | I1509: ='مخزون مفكوك'!I1542&"" | J1509: =N('مخزون مفكوك'!J1542) -> 0 | K1509: =N('مخزون مفكوك'!K1542) -> 0 | L1509: =N('مخزون مفكوك'!U1542) -> 24 | M1509: =SUM(J1509:L1509) -> 24
A1510: ='مخزون مفكوك'!A1543&"" -> 1022581198464 | B1510: ='مخزون مفكوك'!B1543&"" -> بولستر عماني بلو عادي كم ط رجال مشكل 64 | C1510: ='مخزون مفكوك'!C1543&"" -> قطعة | D1510: ='مخزون مفكوك'!D1543&"" -> بولستر عادي | E1510: ='مخزون مفكوك'!E1543&"" -> اكاف بلو | F1510: ='مخزون مفكوك'!F1543&"" -> كم عادى عرض 34 | G1510: ='مخزون مفكوك'!G1543&"" -> 64 | H1510: ='مخزون مفكوك'!H1543&"" -> ملون | I1510: ='مخزون مفكوك'!I1543&"" | J1510: =N('مخزون مفكوك'!J1543) -> 0 | K1510: =N('مخزون مفكوك'!K1543) -> 0 | L1510: =N('مخزون مفكوك'!U1543) -> 12 | M1510: =SUM(J1510:L1510) -> 12
A1511: ='مخزون مفكوك'!A1544&"" -> 1022071198162 | B1511: ='مخزون مفكوك'!B1544&"" -> بولستر عادي بلو عماني عادي زر رجال مشكل | C1511: ='مخزون مفكوك'!C1544&"" -> قطعة | D1511: ='مخزون مفكوك'!D1544&"" -> بولستر عادي | E1511: ='مخزون مفكوك'!E1544&"" -> اكاف بلو | F1511: ='مخزون مفكوك'!F1544&"" -> عماني عادي | G1511: ='مخزون مفكوك'!G1544&"" -> 62 | H1511: ='مخزون مفكوك'!H1544&"" -> ابيض | I1511: ='مخزون مفكوك'!I1544&"" | J1511: =N('مخزون مفكوك'!J1544) -> 0 | K1511: =N('مخزون مفكوك'!K1544) -> 0 | L1511: =N('مخزون مفكوك'!U1544) -> 7 | M1511: =SUM(J1511:L1511) -> 7
A1512: ='مخزون مفكوك'!A1545&"" -> 1022071198454 | B1512: ='مخزون مفكوك'!B1545&"" -> بولستر عادي بلو عماني عادزررج مشكل ملون | C1512: ='مخزون مفكوك'!C1545&"" -> قطعة | D1512: ='مخزون مفكوك'!D1545&"" -> بولستر عادي | E1512: ='مخزون مفكوك'!E1545&"" -> اكاف بلو | F1512: ='مخزون مفكوك'!F1545&"" -> عماني عادي | G1512: ='مخزون مفكوك'!G1545&"" -> 54 | H1512: ='مخزون مفكوك'!H1545&"" -> ملون | I1512: ='مخزون مفكوك'!I1545&"" | J1512: =N('مخزون مفكوك'!J1545) -> 0 | K1512: =N('مخزون مفكوك'!K1545) -> 0 | L1512: =N('مخزون مفكوك'!U1545) -> 12 | M1512: =SUM(J1512:L1512) -> 12
A1513: ='مخزون مفكوك'!A1546&"" -> 10281831873014 | B1513: ='مخزون مفكوك'!B1546&"" -> بولستر ع ترند ثوب سعودي مطرزقلاب ع سح L | C1513: ='مخزون مفكوك'!C1546&"" -> قطعة | D1513: ='مخزون مفكوك'!D1546&"" -> بولستر عادي | E1513: ='مخزون مفكوك'!E1546&"" -> ترند | F1513: ='مخزون مفكوك'!F1546&"" -> ثوب سعودي مطرز | G1513: ='مخزون مفكوك'!G1546&"" -> L | H1513: ='مخزون مفكوك'!H1546&"" -> اسود | I1513: ='مخزون مفكوك'!I1546&"" -> 014 | J1513: =N('مخزون مفكوك'!J1546) -> 0 | K1513: =N('مخزون مفكوك'!K1546) -> 0 | L1513: =N('مخزون مفكوك'!U1546) -> 18 | M1513: =SUM(J1513:L1513) -> 18
A1514: ='مخزون مفكوك'!A1547&"" -> 10281831883014 | B1514: ='مخزون مفكوك'!B1547&"" -> بولسترع ترند ثوب سعودي مطرزقلاب ع سحXL | C1514: ='مخزون مفكوك'!C1547&"" -> قطعة | D1514: ='مخزون مفكوك'!D1547&"" -> بولستر عادي | E1514: ='مخزون مفكوك'!E1547&"" -> ترند | F1514: ='مخزون مفكوك'!F1547&"" -> ثوب سعودي مطرز | G1514: ='مخزون مفكوك'!G1547&"" -> XL | H1514: ='مخزون مفكوك'!H1547&"" -> اسود | I1514: ='مخزون مفكوك'!I1547&"" -> 014 | J1514: =N('مخزون مفكوك'!J1547) -> 0 | K1514: =N('مخزون مفكوك'!K1547) -> 0 | L1514: =N('مخزون مفكوك'!U1547) -> 30 | M1514: =SUM(J1514:L1514) -> 30
A1515: ='مخزون مفكوك'!A1548&"" -> 1031011198454 | B1515: ='مخزون مفكوك'!B1548&"" -> قطن باكستانى نص كم مطرز جال مشكل م 54 | C1515: ='مخزون مفكوك'!C1548&"" -> قطعة | D1515: ='مخزون مفكوك'!D1548&"" -> قطن باكستاني | E1515: ='مخزون مفكوك'!E1548&"" -> إكاف | F1515: ='مخزون مفكوك'!F1548&"" -> نص كم مطرز | G1515: ='مخزون مفكوك'!G1548&"" -> 54 | H1515: ='مخزون مفكوك'!H1548&"" -> ملون | I1515: ='مخزون مفكوك'!I1548&"" | J1515: =N('مخزون مفكوك'!J1548) -> 0 | K1515: =N('مخزون مفكوك'!K1548) -> 0 | L1515: =N('مخزون مفكوك'!U1548) -> 2 | M1515: =SUM(J1515:L1515) -> 2
A1516: ='مخزون مفكوك'!A1549&"" -> 1031011198456 | B1516: ='مخزون مفكوك'!B1549&"" -> قطن باكستانى نص كم مطرز جال مشكل م 56 | C1516: ='مخزون مفكوك'!C1549&"" -> قطعة | D1516: ='مخزون مفكوك'!D1549&"" -> قطن باكستاني | E1516: ='مخزون مفكوك'!E1549&"" -> إكاف | F1516: ='مخزون مفكوك'!F1549&"" -> نص كم مطرز | G1516: ='مخزون مفكوك'!G1549&"" -> 56 | H1516: ='مخزون مفكوك'!H1549&"" -> ملون | I1516: ='مخزون مفكوك'!I1549&"" | J1516: =N('مخزون مفكوك'!J1549) -> 0 | K1516: =N('مخزون مفكوك'!K1549) -> 0 | L1516: =N('مخزون مفكوك'!U1549) -> 9 | M1516: =SUM(J1516:L1516) -> 9
A1517: ='مخزون مفكوك'!A1550&"" -> 1031011198458 | B1517: ='مخزون مفكوك'!B1550&"" -> قطن باكستانى نص كم مطرز جال مشكل م 58 | C1517: ='مخزون مفكوك'!C1550&"" -> قطعة | D1517: ='مخزون مفكوك'!D1550&"" -> قطن باكستاني | E1517: ='مخزون مفكوك'!E1550&"" -> إكاف | F1517: ='مخزون مفكوك'!F1550&"" -> نص كم مطرز | G1517: ='مخزون مفكوك'!G1550&"" -> 58 | H1517: ='مخزون مفكوك'!H1550&"" -> ملون | I1517: ='مخزون مفكوك'!I1550&"" | J1517: =N('مخزون مفكوك'!J1550) -> 0 | K1517: =N('مخزون مفكوك'!K1550) -> 0 | L1517: =N('مخزون مفكوك'!U1550) -> 1 | M1517: =SUM(J1517:L1517) -> 1
... A1659: ='مخزون مفكوك'!A1692&"" -> 31621120 | B1659: ='مخزون مفكوك'!B1692&"" -> سروال رسمي كتان راقي رجالي مقاس 20 | C1659: ='مخزون مفكوك'!C1692&"" -> درزن | D1659: ='مخزون مفكوك'!D1692&"" | E1659: ='مخزون مفكوك'!E1692&"" | F1659: ='مخزون مفكوك'!F1692&"" | G1659: ='مخزون مفكوك'!G1692&"" | H1659: ='مخزون مفكوك'!H1692&"" | I1659: ='مخزون مفكوك'!I1692&"" | J1659: =N('مخزون مفكوك'!J1692) -> 0 | K1659: =N('مخزون مفكوك'!K1692) -> 0 | L1659: =N('مخزون مفكوك'!U1692) -> 5.167 | M1659: =SUM(J1659:L1659) -> 5.167
A1660: الإجمالي | J1660: =SUM(J2:J1659) -> 9016.064 | K1660: =SUM(K2:K1659) -> 80695.469 | L1660: =SUM(L2:L1659) -> 12155.334 | M1660: =SUM(M2:M1659) -> 101866.87
